Workbook
Name DECI_MT_APPORT: [1]SAISIE!$L$46
Name L_ASSISTANTE: [2]TABLES!$E$3:$E$28
Name L_CNI_SYNDIC_MRZ: [2]TABLES!$BA$3:$BA$28
Name L_COMMERCIAL: [2]TABLES!$B$3:$B$28
Name L_COMPTE_SEPARE: [2]TABLES!$AL$3:$AL$28
Name L_COMPTES_COPRO: [2]TABLES!$AO$3:$AO$28
Name L_CONTROLE_SAISIE_DUREE: [3]TABLES!$V$3:$V$10
Name L_GARANT_MRZ: [2]TABLES!$AF$3:$AF$28
Name L_SIGNATURE_PV: [2]TABLES!$AX$3:$AX$28
Name L_TYPE_PRET: [2]TABLES!$O$3:$O$28
Name L_TYPE_SYNDIC: [2]TABLES!$AC$3:$AC$28
Name L_TYPE_TRAVAUX: [2]TABLES!$AI$3:$AI$28
Name o: [1]SAISIE!$L$26
Name P_TOT_MT_C100: [2]PRETS!$C$216
Name P_TOT_MT_EPC: [2]PRETS!$E$216
Name P_TOT_MT_PU: [2]PRETS!$D$216
Name P_TOT_MT_SUB: [2]PRETS!$F$216
Name P_TOT_NB_COPROS: [2]PRETS!$B$216
Name R_CNI_SYNDIC_MRZ: [2]TABLES!$BA$31
Name R_COMMERCIAL: [2]TABLES!$B$31
Name R_COMPTE_SEPARE: [2]TABLES!$AL$31
Name R_COMPTES_COPRO: [2]TABLES!$AO$31
Name R_GARANT_MRZ: [2]TABLES!$AF$31
Name R_SIGNATURE_PV: [2]TABLES!$AX$31
Name R_TYPE_PRET: [2]TABLES!$O$31
Name R_TYPE_SYNDIC: [2]TABLES!$AC$31
Name R_TYPE_TRAVAUX: [2]TABLES!$AI$31
Name S_ADRESSE_SYNDIC: [1]SAISIE!$I$22
Name S_CPOSTAL_SYNDIC: [1]SAISIE!$I$23
Name S_DATE_EXPI_SYNDIC: [1]SAISIE!$M$36
Name S_DATE_VOTE_TRAVAUX: [1]SAISIE!$J$33
Name S_FIBEN_SYNDIC: [1]SAISIE!$L$28
Name S_MT_GARFIN: '[4]FICHE ANALYSE'!#REF!
Name S_MT_TRAVAUX: '[4]FICHE ANALYSE'!#REF!
Name S_NB_LOTS: '[4]FICHE ANALYSE'!#REF!
Name S_NOM_SYNDIC: [1]SAISIE!$I$21
Name S_SIRET: [1]SAISIE!$I$27

Sheet DEMANDE DE PRÊT
F1: Cadres à renseigner
F2: (à compléter par le syndic)
B3: DEMANDE DE PRÊT COLLECTIF EN COPROPRIETE
B4: Financement de travaux par un syndicat des copropriétaires*
B6: SYNDICAT DES COPROPRIETAIRES
B7: Désignation du syndicat des copropriétaires
B8: Adresse de l'immeuble
C9: Code postal | G9: Ville :
B11: SIREN : (si le syndicat des copropriétaires est immatriculé) | G11: Numéro d'immatriculation ANAH : (pour un syndicat des copropriétaires avec des logements)
D12: à vérifier sur www.sirene.fr | J12: à vérifier sur www.registre-coproprietes.gouv.fr
B13: *soumis à la loi n°65-557 du 10 juillet 1965 fixant le statut de la copropriété des immeubles bâtis
B14: IMMEUBLE
B16: Date de construction de l'immeuble : | E16: (JJ/MM/AAAA) | F16: Nombre de lots principaux : (= caves, greniers et parking exclus) | I16: Nombre de logements :
B17: Date de mise à jour de la fiche synthétique de copropriété : | E17: (JJ/MM/AAAA) | H17: A usage : | I17: Nombre de locaux commerciaux : | J17: commercial :
B18: Budget annuel de la copropriété : | F18: Nombre de copropriétaires ou associés (total de l'immeuble) : | I18: Nombre de locaux professionnels :
B20: NATURE ET MONTANTS DES DEPENSES VOTEES
B21: Nature des travaux :
B22: Nom de l'AMO : | F22: Consommation énergétique AVANT travaux | J22: kWhep/m²/an | K22: Gain énergétique
B23: Contact AMO : | F23: Consommation énergétique APRES travaux | K23: =(I22-I23)/I22 -> #DIV/0!
B24: Coût total de l'opération en euros (y compris honoraires, frais et accessoires pour leur montant régulièrement voté) :
B25: SYNDIC OU REPRESENTANT LEGAL
B26: Nom du syndic : | G26: Interlocuteur :
B27: Adresse : | G27: Téléphone :
B28: Code postal : | D28: Ville : | G28: Courriel :
B30: Nom et prénom du gérant / représentant légal du syndic : | G30: Date de désignation ou de renouvellement :
G31: Date d'échéance du mandat en cours :
B33: Nom, prénom et fonction de la personne habilitée à signer le contrat de prêt :
B34: (NB : pour une personne autre que le représentant légal du syndic, joindre une délégation de pouvoir et une pièce d'identité de la personne habilitée)
B35: Téléphone mobile de la personne habilitée (*) : | F35: Courriel de la personne habilitée (*) :
B36: * obligatoire en cas de signature électronique du contrat de prêt
B38: Vous pourrez être amené à être contacté par voie électronique (mail ou sms) à des fins de gestion pour des informations relatives à l’exécution de la présente demande et des produits ou/et services souscrits.
B40: Professionnel
B41: SIREN (ou SIRET si établissement secondaire) : | H41: Date de création du syndic :
B42: N° de carte professionnelle : | G42: Date d'expiration de la carte professionnelle :
B43: Garantie financière : | D43: Organisme émetteur :
D44: Numéro de la garantie : | I44: Montant de la garantie financière :
B45: Assurance R.C. professionnelle - N° et Cie :
B47: Non professionnel | L47: Mod. 05.00.000761 - 04/2018 - MAJ DJ : 04/2018.
B48: Désignation de ses droits (tantièmes ou parts sociales) dans l'immeuble : | H48: sur un total de : | K48: #DIV/0!
B50: PLAN DE FINANCEMENT
...

Sheet LISTE COPROPRIETAIRES ADHERENTS
I1: Cadres à renseigner | K1: Des formulaires de plus de 500 lignes sont disponibles sur demande | R1: MODE D'EMPLOI
D2: DESIGNATION DU SYNDICAT DES COPROPRIETAIRES : | J2: TYPES DE PRÊTS | R2: 1) RENSEIGNER les rubriques avec un encadré vert 2) FILTRER sur la colonne "NOM ou RAISON SOCIALE" en sélectionnant les cellules renseignées (= décocher les cases "vides") 3) IMPRIMER le document, le dater, le signer (+ cachet) et le joindre au dossier à adresser à la Caisse d'Epargne 4) ADRESSER le fichier Excel par mail à la Caisse d'Epargne : agence.copro@cegee.caisse-epargne.fr
D3: ='DEMANDE DE PRÊT'!D7 -> 0 | J3: AVANCE DE SUBVENTIONS | L3: ECO-PTZ COPRO | N3: COPRO 100 (ou COPRO 1) complémentaire
B5: LISTE DES COPROPRIETAIRES DEMANDANT A PARTICIPER A L'EMPRUNT
B6: Si besoin : Votre REF. : n° lot, n° coprop. (saisie libre) | D6: NOM et prénoms des copropriétaires ou RAISON SOCIALE NB : si multipropriétaire : 1 ligne par local RAPPEL : pour un ECO-PTZ : logements occupés en résidence principale uniquement | E6: Quote-part des travaux sur les parties communes | F6: Montant des travaux sur les parties privatives | G6: Total de la quote-part des travaux (honoraires inclus) | H6: Quote-part des subventions collectives | I6: Montant des subventions individuelles | J6: Demande de préfinancement de la part individuelle des subventions (OUI / NON) | K6: Le cas échéant : Autres déductions (fonds travaux ALUR, provisions versées) (CEE EXCLUS) | L6: Montant du reste à charge | M6: Montant d'emprunt demandé dans la limite du reste à charge (arrondi à l'euro inférieur) | P6: Etat des charges courantes Le copropriétaire est-il à jour de ses charges courantes (sans retard de plus de 2 trimestres) sur les 12 derniers mois ? (OUI / NON)
C7: Tantièmes | M7: Au titre de l'ECO-PTZ Durée choisie (même durée) | N7: Au titre du COPRO 100 (ou COPRO 1) (lots non éligibles à l'ECO-PTZ ou au-delà du plafond) | O7: COPRO 100 ou COPRO1 Durée d'emprunt choisie
E8: (A) | F8: (B) | G8: (C) = (A + B) | H8: (D) | I8: (E) | K8: (F) | L8: (G) = (C - D - E - F) | M8: 15 ans
A9: 1 | B9: 100 | D9: AZERTY | E9: 10000 | G9: =E9+F9 -> 10000 | H9: 2000 | J9: NON | L9: =G9-H9-I9-K9 -> 8000 | M9: 8000 | P9: OUI
A10: 2 | B10: 101 | D10: MEUBLE TOURISTIQUE | E10: 10000 | G10: =E10+F10 -> 10000 | H10: 2000 | L10: =G10-H10-I10-K10 -> 8000 | N10: 8000 | P10: OUI
A11: 3 | B11: 102 | D11: CRESUS | E11: 10000 | G11: =E11+F11 -> 10000 | H11: 2000 | L11: =G11-H11-I11-K11 -> 8000 | P11: NON
A12: 4 | G12: =E12+F12 -> 0 | L12: =G12-H12-I12-K12 -> 0
A13: 5 | G13: =E13+F13 -> 0 | L13: =G13-H13-I13-K13 -> 0
A14: 6 | G14: =E14+F14 -> 0 | L14: =G14-H14-I14-K14 -> 0
A15: 7 | G15: =E15+F15 -> 0 | L15: =G15-H15-I15-K15 -> 0
A16: 8 | G16: =E16+F16 -> 0 | L16: =G16-H16-I16-K16 -> 0
A17: 9 | G17: =E17+F17 -> 0 | L17: =G17-H17-I17-K17 -> 0
A18: 10 | G18: =E18+F18 -> 0 | L18: =G18-H18-I18-K18 -> 0
A19: 11 | G19: =E19+F19 -> 0 | L19: =G19-H19-I19-K19 -> 0
A20: 12 | G20: =E20+F20 -> 0 | L20: =G20-H20-I20-K20 -> 0
A21: 13 | G21: =E21+F21 -> 0 | L21: =G21-H21-I21-K21 -> 0
A22: 14 | G22: =E22+F22 -> 0 | L22: =G22-H22-I22-K22 -> 0
A23: 15 | G23: =E23+F23 -> 0 | L23: =G23-H23-I23-K23 -> 0
... A508: 500 | G508: =E508+F508 -> 0 | L508: =G508-H508-I508-K508 -> 0
D509: TOTAL A FINANCER en euros | E509: =SUM(E9:E508) -> 30000 | F509: =SUM(F9:F508) -> 0 | G509: =SUM(G9:G508) -> 30000 | H509: =SUM(H9:H508) -> 6000 | I509: =SUM(I9:I508) -> 0 | J509: =SUM(J9:J508) -> 0 | K509: =SUM(K9:K508) -> 0 | L509: =SUM(L9:L508) -> 24000 | ... N509: =SUM(N9:N508) -> 8000 | O509: TOTAL A FINANCER
D510: Je soussigné déclare qu’à ma connaissance aucun des titulaires de lots participants de l’emprunt n’est, à ce jour, en état de liquidation de biens, règlement judiciaire, faillite ou banqueroute. A peine de forclusion, il est rappelé que les participants à l’emprunt ont notifié leur adhésion dans les conditions et délais légaux prévus par l’article 26-4 de la loi n °65-557 du 10 juillet 1965 fixant le statut de la copropriété des immeubles bâtis. Il est également rappelé que vous ne pouvez signer le contrat de prêt avant l’expiration du délai de recours de deux mois à compter de la notification de la décision d’emprunt prise en assemblée générale des copropriétaires, conformément à l’article 26-4 de la loi n°65-557 du 10 juillet 1965.
D511: Fait à | J511: , le
D512: Signature du Syndic ou Représentant légal certifiée sincère et véritable | J512: Cachet du Syndic
D513: La Caisse d’Epargne Grand Est Europe recueille des données à caractère personnel vous concernant et met en œuvre des mesures techniques et organisationnelles appropriées pour s’assurer que les traitements de données à caractère personnel sont effectués conformément à la législation applicable. Les données recueillies sont obligatoires. A défaut votre demande ne pourrait pas être traitée ou son traitement s’en trouverait retardé. Vos données sont traitées pour établir une proposition de financement sur la base des données recueillies. Ces traitements ont pour bases juridiques : la gestion et exécution de votre demande, nos obligations légales, l’intérêt légitime et votre consentement s’agissant de la prospection commerciale. Vos données sont destinées au prêteur, responsable de traitement. Lorsque vous êtes entré en contact avec nous et que votre demande n’a pas été suivie d’un contrat de crédit, nous conservons vos données pendant une durée limitée à la finalité initialement poursuivie. Les données personnelles relatives à un prospect non client sont conservées, à des fins de prospection commerciale, pendant une durée maximale de trois ans à compter du dernier contact émanant du prospect. Vous bénéficiez d’un droit d’accès à vos données à caractère personnel. Dans les conditions prévues par la loi, vous pouvez également demander une limitation du traitement, la rectification ou l’effacement des données vous concernant, ainsi que leur portabilité, ou communiquer des directives sur le sort de ces données en cas de décès. Vous disposez également du droit de vous opposer au traitement de vos données à des fins de prospection commerciale. Ces droits peuvent, sous réserve de justifier de votre identité par la production d’une pièce d’identité, être exercés à tout moment à l’adresse suivante : - Par courrier postal : Caisse d’Epargne Grand Est Europe - Service relations clientèle - 5, Parvis des Droits de l’Homme - 57012 Metz Cedex - Par courriel : relationsclientele@cegee.caisse-epargne.fr Si vous souhaitez en savoir plus ou contacter notre Délégué à la Protection des Données, vous pouvez lui écrire à l’adresse suivante : Caisse d’Epargne Grand Est Europe – Délégué à la Protection des Données - 5, Parvis des Droits de l’Homme - 57012 Metz Cedex. Par courriel : delegue-protection-donnees@cegee.caisse-epargne.fr. Les personnes concernées ont le droit d’introduire une réclamation auprès d’une autorité de contrôle en charge de la protection des personnes physiques à l’égard du traitement des données à caractère personnel. En France, l’autorité de contrôle est : Commission Nationale de l’Informatique et des Libertés (CNIL) 3 place de Fontenoy TSA 80715 75334 PARIS Cedex 07. Pour plus d’information, consultez notre notice d’information sur la protection des données personnelles à tout moment sur notre site internet https://www.caisse-epargne.fr/grand-est-europe/votre-banque/reglementation/protection-de-vos-donnees-personnelles/ ou sur simple demande auprès de notre établissement.
D514: La Caisse d’Epargne et de Prévoyance Grand Est Europe, Banque coopérative régie par les articles L.512-85 et suivants du Code Monétaire et Financier, société anonyme à Directoire et Conseil d’Orientation et de Surveillance au capital de 681.876.700 € - siège social à STRASBOURG (67100), 1, avenue du Rhin – 775 618 622 RCS STRASBOURG – immatriculée à l’ORIAS sous le n° 07 004 738.

Sheet PLAN DE FINANCEMENT
A1: PLAN DE FINANCEMENT GLOBAL | J1: Date de début des travaux (JJ/MM/AAAA)
A2: DESIGNATION DU SYNDICAT DES COPROPRIETAIRES : | B2: ='LISTE COPROPRIETAIRES ADHERENTS'!D3 -> 0 | J2: Date prévisionnelle de fin des travaux (JJ/MM/AAAA)
A4: EMPLOIS (Travaux) | F4: € TTC | G4: MONTANTS ELIGIBLES ECO PTZ SELON DEVIS RGE | H4: Montants éligibles aux seuls copropriétaires adhérents | J4: RESSOURCES (Subventions, Prêts, Apports…) | K4: € TTC
A5: 1. NATURE DES TRAVAUX | B5: Date vote et N° réso | C5: Budget voté | D5: Entreprises | E5: Date devis ou OS | J5: A - SUBVENTIONS PUBLIQUES AU SYNDICAT (MONTANTS PREFINANCES)
A6: isolation | C6: 100000 | D6: SA RENOV | F6: 100000 | G6: 100000 | H6: 90000 | J6: ANAH | K6: 10000
J7: Climaxion | K7: 5000
J8: Aide de l'EMS pour étude MOE | K8: 5000
J9: Aide de l'EMS pour travaux
A19: Sous-total travaux (y compris aléas) | C19: =SUM(C6:C18) -> 100000 | F19: =SUM(F6:F18) -> 100000 | G19: =SUM(G6:G18) -> 100000 | H19: =SUM(H6:H18) -> 90000 | J19: TOTAL SUBVENTIONS PUBLIQUES (MONTANTS PREFINANCES) | K19: =SUM(K6:K18) -> 20000
A20: 2. HONORAIRES DIVERS | J20: B - AUTRES FINANCEMENTS
A21: Bureau de contrôle | J21: Fonds Propres des copropriétaires | K21: =F31-K19-SUM(K22:K29) -> 64000
A22: Coordinateur SPS | J22: Demande d'ECO-PTZ | K22: ='LISTE COPROPRIETAIRES ADHERENTS'!M509 -> 8000
A23: Maîtrise d'œuvre - phase travaux | J23: Demande de COPRO 100 (ou COPRO1) complémentaire | K23: ='LISTE COPROPRIETAIRES ADHERENTS'!N509 -> 8000
A24: AMO - phase travaux | J24: Montant des factures déjà réglées par le syndic
A25: Assurance dommages-ouvrage
A26: honoraire syndic
A27: Test d'étanchéité à l'air finaux
A30: Sous-total honoraires | C30: =SUM(C21:C29) -> 0 | F30: =SUM(F21:F29) -> 0 | G30: =SUM(G21:G29) -> 0 | H30: =SUM(H21:H29) -> 0 | J30: Sous-total Fonds Propres et Assimilés | K30: =SUM(K21:K29) -> 80000
A31: TOTAL GENERAL (1+2) | C31: =C30+C19 -> 100000 | F31: =F30+F19 -> 100000 | G31: =G19+G30 -> 100000 | H31: =H19+H30 -> 90000 | J31: TOTAL GENERAL (A+B) | K31: =K19+K30 -> 100000
A33: Date, cachet et signature du syndic :
